Traceback (most recent call last):
  File "/Users/shijie/miniconda3/lib/python3.8/site-packages/jupyter_cache/executors/utils.py", line 51, in single_nb_execution
    executenb(
  File "/Users/shijie/miniconda3/lib/python3.8/site-packages/nbclient/client.py", line 1204, in execute
    return NotebookClient(nb=nb, resources=resources, km=km, **kwargs).execute()
  File "/Users/shijie/miniconda3/lib/python3.8/site-packages/nbclient/util.py", line 84, in wrapped
    return just_run(coro(*args, **kwargs))
  File "/Users/shijie/miniconda3/lib/python3.8/site-packages/nbclient/util.py", line 62, in just_run
    return loop.run_until_complete(coro)
  File "/Users/shijie/miniconda3/lib/python3.8/asyncio/base_events.py", line 616, in run_until_complete
    return future.result()
  File "/Users/shijie/miniconda3/lib/python3.8/site-packages/nbclient/client.py", line 663, in async_execute
    await self.async_execute_cell(
  File "/Users/shijie/miniconda3/lib/python3.8/site-packages/nbclient/client.py", line 965, in async_execute_cell
    await self._check_raise_for_error(cell, cell_index, exec_reply)
  File "/Users/shijie/miniconda3/lib/python3.8/site-packages/nbclient/client.py", line 862, in _check_raise_for_error
    raise CellExecutionError.from_cell_and_msg(cell, exec_reply_content)
nbclient.exceptions.CellExecutionError: An error occurred while executing the following cell:
------------------
1/0
------------------

[0;31m---------------------------------------------------------------------------[0m
[0;31mZeroDivisionError[0m                         Traceback (most recent call last)
Input [0;32mIn [4][0m, in [0;36m<module>[0;34m[0m
[0;32m----> 1[0m [38;5;241;43m1[39;49m[38;5;241;43m/[39;49m[38;5;241;43m0[39;49m

[0;31mZeroDivisionError[0m: division by zero
ZeroDivisionError: division by zero

